Traceback (most recent call last):
  File "/usr/local/lib/python3.9/site-packages/sqlalchemy/engine/base.py", line 145, in __init__
    self._dbapi_connection = engine.raw_connection()
  File "/usr/local/lib/python3.9/site-packages/sqlalchemy/engine/base.py", line 3297, in raw_connection
    return self.pool.connect()
  File "/usr/local/lib/python3.9/site-packages/sqlalchemy/pool/base.py", line 449, in connect
    return _ConnectionFairy._checkout(self)
  File "/usr/local/lib/python3.9/site-packages/sqlalchemy/pool/base.py", line 1264, in _checkout
    fairy = _ConnectionRecord.checkout(pool)
  File "/usr/local/lib/python3.9/site-packages/sqlalchemy/pool/base.py", line 713, in checkout
    rec = pool._do_get()
  File "/usr/local/lib/python3.9/site-packages/sqlalchemy/pool/impl.py", line 180, in _do_get
    self._dec_overflow()
  File "/usr/local/lib/python3.9/site-packages/sqlalchemy/util/langhelpers.py", line 224, in __exit__
    raise exc_value.with_traceback(exc_tb)
  File "/usr/local/lib/python3.9/site-packages/sqlalchemy/pool/impl.py", line 177, in _do_get
    return self._create_connection()
  File "/usr/local/lib/python3.9/site-packages/sqlalchemy/pool/base.py", line 390, in _create_connection
    return _ConnectionRecord(self)
  File "/usr/local/lib/python3.9/site-packages/sqlalchemy/pool/base.py", line 675, in __init__
    self.__connect()
  File "/usr/local/lib/python3.9/site-packages/sqlalchemy/pool/base.py", line 902, in __connect
    pool.logger.debug("Error on connect(): %s", e)
  File "/usr/local/lib/python3.9/site-packages/sqlalchemy/util/langhelpers.py", line 224, in __exit__
    raise exc_value.with_traceback(exc_tb)
  File "/usr/local/lib/python3.9/site-packages/sqlalchemy/pool/base.py", line 897, in __connect
    self.dbapi_connection = connection = pool._invoke_creator(self)
  File "/usr/local/lib/python3.9/site-packages/sqlalchemy/engine/create.py", line 646, in connect
    return dialect.connect(*cargs, **cparams)
  File "/usr/local/lib/python3.9/site-packages/sqlalchemy/engine/default.py", line 625, in connect
    return self.loaded_dbapi.connect(*cargs, **cparams)  # type: ignore[no-any-return]  # NOQA: E501
  File "/usr/local/lib/python3.9/site-packages/psycopg2/__init__.py", line 122, in connect
    conn = _connect(dsn, connection_factory=connection_factory, **kwasync)
psycopg2.OperationalError: connection to server at "postgresql" (172.30.15.66), port 5432 failed: FATAL:  database "test_db" does not exist


The above exception was the direct cause of the following exception:

Traceback (most recent call last):
  File "/usr/local/bin/uvicorn", line 8, in <module>
    sys.exit(main())
  File "/usr/local/lib/python3.9/site-packages/click/core.py", line 1161, in __call__
    return self.main(*args, **kwargs)
  File "/usr/local/lib/python3.9/site-packages/click/core.py", line 1082, in main
    rv = self.invoke(ctx)
  File "/usr/local/lib/python3.9/site-packages/click/core.py", line 1443, in invoke
    return ctx.invoke(self.callback, **ctx.params)
  File "/usr/local/lib/python3.9/site-packages/click/core.py", line 788, in invoke
    return __callback(*args, **kwargs)
  File "/usr/local/lib/python3.9/site-packages/uvicorn/main.py", line 413, in main
    run(
  File "/usr/local/lib/python3.9/site-packages/uvicorn/main.py", line 580, in run
    server.run()
  File "/usr/local/lib/python3.9/site-packages/uvicorn/server.py", line 67, in run
    return asyncio.run(self.serve(sockets=sockets))
  File "/usr/local/lib/python3.9/asyncio/runners.py", line 44, in run
    return loop.run_until_complete(main)
  File "/usr/local/lib/python3.9/asyncio/base_events.py", line 647, in run_until_complete
    return future.result()
  File "/usr/local/lib/python3.9/site-packages/uvicorn/server.py", line 71, in serve
    await self._serve(sockets)
  File "/usr/local/lib/python3.9/site-packages/uvicorn/server.py", line 78, in _serve
    config.load()
  File "/usr/local/lib/python3.9/site-packages/uvicorn/config.py", line 436, in load
    self.loaded_app = import_from_string(self.app)
  File "/usr/local/lib/python3.9/site-packages/uvicorn/importer.py", line 19, in import_from_string
    module = importlib.import_module(module_str)
  File "/usr/local/lib/python3.9/importlib/__init__.py", line 127, in import_module
    return _bootstrap._gcd_import(name[level:], package, level)
  File "<frozen importlib._bootstrap>", line 1030, in _gcd_import
  File "<frozen importlib._bootstrap>", line 1007, in _find_and_load
  File "<frozen importlib._bootstrap>", line 986, in _find_and_load_unlocked
  File "<frozen importlib._bootstrap>", line 680, in _load_unlocked
  File "<frozen importlib._bootstrap_external>", line 850, in exec_module
  File "<frozen importlib._bootstrap>", line 228, in _call_with_frames_removed
  File "/app/authentication/main.py", line 7, in <module>
    Base.metadata.create_all(bind=engine)
  File "/usr/local/lib/python3.9/site-packages/sqlalchemy/sql/schema.py", line 5924, in create_all
    bind._run_ddl_visitor(
  File "/usr/local/lib/python3.9/site-packages/sqlalchemy/engine/base.py", line 3247, in _run_ddl_visitor
    with self.begin() as conn:
  File "/usr/local/lib/python3.9/contextlib.py", line 119, in __enter__
    return next(self.gen)
  File "/usr/local/lib/python3.9/site-packages/sqlalchemy/engine/base.py", line 3237, in begin
    with self.connect() as conn:
  File "/usr/local/lib/python3.9/site-packages/sqlalchemy/engine/base.py", line 3273, in connect
    return self._connection_cls(self)
  File "/usr/local/lib/python3.9/site-packages/sqlalchemy/engine/base.py", line 147, in __init__
    Connection._handle_dbapi_exception_noconnection(
  File "/usr/local/lib/python3.9/site-packages/sqlalchemy/engine/base.py", line 2436, in _handle_dbapi_exception_noconnection
    raise sqlalchemy_exception.with_traceback(exc_info[2]) from e
  File "/usr/local/lib/python3.9/site-packages/sqlalchemy/engine/base.py", line 145, in __init__
    self._dbapi_connection = engine.raw_connection()
  File "/usr/local/lib/python3.9/site-packages/sqlalchemy/engine/base.py", line 3297, in raw_connection
    return self.pool.connect()
  File "/usr/local/lib/python3.9/site-packages/sqlalchemy/pool/base.py", line 449, in connect
    return _ConnectionFairy._checkout(self)
  File "/usr/local/lib/python3.9/site-packages/sqlalchemy/pool/base.py", line 1264, in _checkout
    fairy = _ConnectionRecord.checkout(pool)
  File "/usr/local/lib/python3.9/site-packages/sqlalchemy/pool/base.py", line 713, in checkout
    rec = pool._do_get()
  File "/usr/local/lib/python3.9/site-packages/sqlalchemy/pool/impl.py", line 180, in _do_get
    self._dec_overflow()
  File "/usr/local/lib/python3.9/site-packages/sqlalchemy/util/langhelpers.py", line 224, in __exit__
    raise exc_value.with_traceback(exc_tb)
  File "/usr/local/lib/python3.9/site-packages/sqlalchemy/pool/impl.py", line 177, in _do_get
    return self._create_connection()
  File "/usr/local/lib/python3.9/site-packages/sqlalchemy/pool/base.py", line 390, in _create_connection
    return _ConnectionRecord(self)
  File "/usr/local/lib/python3.9/site-packages/sqlalchemy/pool/base.py", line 675, in __init__
    self.__connect()
  File "/usr/local/lib/python3.9/site-packages/sqlalchemy/pool/base.py", line 902, in __connect
    pool.logger.debug("Error on connect(): %s", e)
  File "/usr/local/lib/python3.9/site-packages/sqlalchemy/util/langhelpers.py", line 224, in __exit__
    raise exc_value.with_traceback(exc_tb)
  File "/usr/local/lib/python3.9/site-packages/sqlalchemy/pool/base.py", line 897, in __connect
    self.dbapi_connection = connection = pool._invoke_creator(self)
  File "/usr/local/lib/python3.9/site-packages/sqlalchemy/engine/create.py", line 646, in connect
    return dialect.connect(*cargs, **cparams)
  File "/usr/local/lib/python3.9/site-packages/sqlalchemy/engine/default.py", line 625, in connect
    return self.loaded_dbapi.connect(*cargs, **cparams)  # type: ignore[no-any-return]  # NOQA: E501
  File "/usr/local/lib/python3.9/site-packages/psycopg2/__init__.py", line 122, in connect
    conn = _connect(dsn, connection_factory=connection_factory, **kwasync)
sqlalchemy.exc.OperationalError: (psycopg2.OperationalError) connection to server at "postgresql" (172.30.15.66), port 5432 failed: FATAL:  database "test_db" does not exist

(Background on this error at: https://sqlalche.me/e/20/e3q8)
